[2023-07-30 13:13:01,913: WARNING/MainProcess] DB Reset: Account for new __version__ field
[2023-07-30 13:20:47,815: ERROR/MainProcess] Removing corrupted schedule file 'celerybeat-schedule': error(11, 'Resource temporarily unavailable')
Traceback (most recent call last):
  File "/home/binod/celery_with_django/venv3/lib/python3.10/site-packages/celery/beat.py", line 528, in setup_schedule
    self._store = self._open_schedule()
  File "/home/binod/celery_with_django/venv3/lib/python3.10/site-packages/celery/beat.py", line 518, in _open_schedule
    return self.persistence.open(self.schedule_filename, writeback=True)
  File "/usr/local/lib/python3.10/shelve.py", line 243, in open
    return DbfilenameShelf(filename, flag, protocol, writeback)
  File "/usr/local/lib/python3.10/shelve.py", line 227, in __init__
    Shelf.__init__(self, dbm.open(filename, flag), protocol, writeback)
  File "/usr/local/lib/python3.10/dbm/__init__.py", line 95, in open
    return mod.open(file, flag, mode)
_gdbm.error: [Errno 11] Resource temporarily unavailable: 'celerybeat-schedule'
[2023-07-30 13:22:41,421: ERROR/MainProcess] Removing corrupted schedule file 'celerybeat-schedule': error(11, 'Resource temporarily unavailable')
Traceback (most recent call last):
  File "/home/binod/celery_with_django/venv3/lib/python3.10/site-packages/celery/beat.py", line 528, in setup_schedule
    self._store = self._open_schedule()
  File "/home/binod/celery_with_django/venv3/lib/python3.10/site-packages/celery/beat.py", line 518, in _open_schedule
    return self.persistence.open(self.schedule_filename, writeback=True)
  File "/usr/local/lib/python3.10/shelve.py", line 243, in open
    return DbfilenameShelf(filename, flag, protocol, writeback)
  File "/usr/local/lib/python3.10/shelve.py", line 227, in __init__
    Shelf.__init__(self, dbm.open(filename, flag), protocol, writeback)
  File "/usr/local/lib/python3.10/dbm/__init__.py", line 95, in open
    return mod.open(file, flag, mode)
_gdbm.error: [Errno 11] Resource temporarily unavailable: 'celerybeat-schedule'
[2023-07-30 13:24:10,823: ERROR/MainProcess] Removing corrupted schedule file 'celerybeat-schedule': error(11, 'Resource temporarily unavailable')
Traceback (most recent call last):
  File "/home/binod/celery_with_django/venv3/lib/python3.10/site-packages/celery/beat.py", line 528, in setup_schedule
    self._store = self._open_schedule()
  File "/home/binod/celery_with_django/venv3/lib/python3.10/site-packages/celery/beat.py", line 518, in _open_schedule
    return self.persistence.open(self.schedule_filename, writeback=True)
  File "/usr/local/lib/python3.10/shelve.py", line 243, in open
    return DbfilenameShelf(filename, flag, protocol, writeback)
  File "/usr/local/lib/python3.10/shelve.py", line 227, in __init__
    Shelf.__init__(self, dbm.open(filename, flag), protocol, writeback)
  File "/usr/local/lib/python3.10/dbm/__init__.py", line 95, in open
    return mod.open(file, flag, mode)
_gdbm.error: [Errno 11] Resource temporarily unavailable: 'celerybeat-schedule'
[2023-07-30 13:31:30,840: ERROR/MainProcess] Removing corrupted schedule file 'celerybeat-schedule': error(11, 'Resource temporarily unavailable')
Traceback (most recent call last):
  File "/home/binod/celery_with_django/venv3/lib/python3.10/site-packages/celery/beat.py", line 528, in setup_schedule
    self._store = self._open_schedule()
  File "/home/binod/celery_with_django/venv3/lib/python3.10/site-packages/celery/beat.py", line 518, in _open_schedule
    return self.persistence.open(self.schedule_filename, writeback=True)
  File "/usr/local/lib/python3.10/shelve.py", line 243, in open
    return DbfilenameShelf(filename, flag, protocol, writeback)
  File "/usr/local/lib/python3.10/shelve.py", line 227, in __init__
    Shelf.__init__(self, dbm.open(filename, flag), protocol, writeback)
  File "/usr/local/lib/python3.10/dbm/__init__.py", line 95, in open
    return mod.open(file, flag, mode)
_gdbm.error: [Errno 11] Resource temporarily unavailable: 'celerybeat-schedule'
[2023-07-30 13:38:05,513: INFO/MainProcess] beat: Starting...
[2023-07-30 13:38:05,517: ERROR/MainProcess] Removing corrupted schedule file 'celerybeat-schedule': error(11, 'Resource temporarily unavailable')
Traceback (most recent call last):
  File "/home/binod/celery_with_django/venv3/lib/python3.10/site-packages/celery/beat.py", line 528, in setup_schedule
    self._store = self._open_schedule()
  File "/home/binod/celery_with_django/venv3/lib/python3.10/site-packages/celery/beat.py", line 518, in _open_schedule
    return self.persistence.open(self.schedule_filename, writeback=True)
  File "/usr/local/lib/python3.10/shelve.py", line 243, in open
    return DbfilenameShelf(filename, flag, protocol, writeback)
  File "/usr/local/lib/python3.10/shelve.py", line 227, in __init__
    Shelf.__init__(self, dbm.open(filename, flag), protocol, writeback)
  File "/usr/local/lib/python3.10/dbm/__init__.py", line 95, in open
    return mod.open(file, flag, mode)
_gdbm.error: [Errno 11] Resource temporarily unavailable: 'celerybeat-schedule'
[2023-07-30 13:46:01,442: INFO/MainProcess] beat: Starting...
[2023-07-30 13:46:01,446: ERROR/MainProcess] Removing corrupted schedule file 'celerybeat-schedule': error(11, 'Resource temporarily unavailable')
Traceback (most recent call last):
  File "/home/binod/celery_with_django/venv3/lib/python3.10/site-packages/celery/beat.py", line 528, in setup_schedule
    self._store = self._open_schedule()
  File "/home/binod/celery_with_django/venv3/lib/python3.10/site-packages/celery/beat.py", line 518, in _open_schedule
    return self.persistence.open(self.schedule_filename, writeback=True)
  File "/usr/local/lib/python3.10/shelve.py", line 243, in open
    return DbfilenameShelf(filename, flag, protocol, writeback)
  File "/usr/local/lib/python3.10/shelve.py", line 227, in __init__
    Shelf.__init__(self, dbm.open(filename, flag), protocol, writeback)
  File "/usr/local/lib/python3.10/dbm/__init__.py", line 95, in open
    return mod.open(file, flag, mode)
_gdbm.error: [Errno 11] Resource temporarily unavailable: 'celerybeat-schedule'
[2023-07-30 13:46:59,414: INFO/MainProcess] beat: Starting...
[2023-07-30 13:46:59,419: ERROR/MainProcess] Removing corrupted schedule file 'celerybeat-schedule': error(11, 'Resource temporarily unavailable')
Traceback (most recent call last):
  File "/home/binod/celery_with_django/venv3/lib/python3.10/site-packages/celery/beat.py", line 528, in setup_schedule
    self._store = self._open_schedule()
  File "/home/binod/celery_with_django/venv3/lib/python3.10/site-packages/celery/beat.py", line 518, in _open_schedule
    return self.persistence.open(self.schedule_filename, writeback=True)
  File "/usr/local/lib/python3.10/shelve.py", line 243, in open
    return DbfilenameShelf(filename, flag, protocol, writeback)
  File "/usr/local/lib/python3.10/shelve.py", line 227, in __init__
    Shelf.__init__(self, dbm.open(filename, flag), protocol, writeback)
  File "/usr/local/lib/python3.10/dbm/__init__.py", line 95, in open
    return mod.open(file, flag, mode)
_gdbm.error: [Errno 11] Resource temporarily unavailable: 'celerybeat-schedule'
